Workbook
Name \0: #REF!
Name \a: #REF!
Name \c: #N/A
Name \d: #REF!
Name \j: #REF!
Name \k: #REF!
Name \l: #REF!
Name \n: #REF!
Name \p: #REF!
Name \t: #REF!
Name \v: #REF!
Name \w: #REF!
Name \x: #REF!
Name \z: #REF!
Name _____NA5: #REF!
Name ___NA5: #REF!
Name __ACC0320: #REF!
Name __FDS_UNIQUE_RANGE_ID_GENERATOR_COUNTER: 1
Name __JJJ3: #REF!
Name __JJJ4: #REF!
Name __JJJ5: #REF!
Name __key1: #REF!
Name __May2007: #REF!
Name __may2008: #REF!
Name __NA1: #REF!
Name __NA2: #REF!
Name __NA3: #REF!
Name __NA4: #REF!
Name __NA5: #REF!
Name _01_Apr: #REF!
Name _01_May: #REF!
Name _ACC0320: #REF!
Name _APR2001: #REF!
Name _AUG2001: #REF!
Name _cat1: #REF!
Name _cat2: #REF!
Name _cat3: #REF!
Name _Dec02: #REF!
Name _Dec03: #REF!
Name _DEC2001: #REF!
Name _FEB2001: #REF!
Name _FEB2002: #REF!
Name _inv1: #REF!
Name _JAN02: #REF!
Name _JAN2001: #REF!
Name _JAN2002: #REF!
Name _JJJ1: #REF!
Name _JJJ2: #REF!
Name _JJJ3: #REF!
Name _JJJ4: #REF!
Name _JJJ5: #REF!
Name _JUL2001: #REF!
Name _JUN2001: #REF!
Name _kl1: #REF!
Name _LD1: #REF!
Name _loc3: #REF!
Name _Ma2005: #REF!
Name _MAR2001: #REF!
Name _MAR2002: #REF!
Name _MAY2001: #REF!

Sheet Project Planner
B1: Project Planner
B2: Select a period to highlight at right. A legend describing the charting follows. | G2: Period Highlight: | H2: 1 | K2: Plan Duration | Q2: Actual Start | V2: % Complete | AA2: Actual (beyond plan) | AI2: % Complete (beyond plan)
B3: ACTIVITY | C3: PLAN START | D3: PLAN DURATION | E3: ACTUAL START | F3: ACTUAL DURATION | G3: PERCENT COMPLETE | H3: PERIODS
H4: 1 | I4: 2 | J4: 3 | K4: 4 | L4: 5 | M4: 6 | N4: 7 | O4: 8 | P4: 9 | Q4: 10 | R4: 11 | S4: 12 | T4: 13 | U4: 14 | V4: 15 | W4: 16 | X4: 17 | Y4: 18 | Z4: 19 | AA4: 20 | AB4: 21 | AC4: 22 | AD4: 23 | AE4: 24 | AF4: 25 | AG4: 26 | AH4: 27 | AI4: 28 | AJ4: 29 | AK4: 30 | AL4: 31 | AM4: 32 | AN4: 33 | AO4: 34 | AP4: 35 | AQ4: 36 | AR4: 37 | AS4: 38 | AT4: 39 | AU4: 40 | AV4: 41 | AW4: 42 | AX4: 43 | AY4: 44 | AZ4: 45 | BA4: 46 | BB4: 47 | BC4: 48 | BD4: 49 | BE4: 50 | BF4: 51 | BG4: 52 | BH4: 53 | BI4: 54 | BJ4: 55 | BK4: 56 | BL4: 57 | BM4: 58 | BN4: 59 | BO4: 60
B5: ='DO NOT USE 2023-2024 Production'!B125 -> Sandia Academy | C5: 1 | D5: 5 | E5: 1 | F5: 4 | G5: 0.25
B6: Activity 02 | C6: 1 | D6: 6 | E6: 1 | F6: 6 | G6: 1
B7: Activity 03 | C7: 2 | D7: 4 | E7: 2 | F7: 5 | G7: 0.35
B8: Activity 04 | C8: 4 | D8: 8 | E8: 4 | F8: 6 | G8: 0.1
B9: Activity 05 | C9: 4 | D9: 2 | E9: 4 | F9: 8 | G9: 0.85
B10: Activity 06 | C10: 4 | D10: 3 | E10: 4 | F10: 6 | G10: 0.85
B11: Activity 07 | C11: 5 | D11: 4 | E11: 5 | F11: 3 | G11: 0.5
B12: Activity 08 | C12: 5 | D12: 2 | E12: 5 | F12: 5 | G12: 0.6
B13: Activity 09 | C13: 5 | D13: 2 | E13: 5 | F13: 6 | G13: 0.75
B14: Activity 10 | C14: 6 | D14: 5 | E14: 6 | F14: 7 | G14: 1
B15: Activity 11 | C15: 6 | D15: 1 | E15: 5 | F15: 8 | G15: 0.6
B16: Activity 12 | C16: 9 | D16: 3 | E16: 9 | F16: 3 | G16: 0
B17: Activity 13 | C17: 9 | D17: 6 | E17: 9 | F17: 7 | G17: 0.5
... B30: Activity 26 | C30: 16 | D30: 28 | E30: 16 | F30: 30 | G30: 0.5

Sheet Sheet2
A3: Sum of Estimated Value
A4: 1.3757634e+08
D5: Joe | E5: Lori
D6: Diana | E6: Kenny
D7: Sandra | E7: Pick one
D8: Sandra | E8: Pick one

Sheet 2026 Sales Pipeline
A1: SCM Sales Pipeline 2026 & Beyond
A2: Customer | B2: Project Name | C2: BDM | D2: Job Number | E2: Contract Value | F2: Building(s) | G2: Floor(s) | H2: Start Date for Production | I2: District Occupancy Date | J2: Confidence Level | K2: Current Status/Notes | L2: Contract Type | M2: Bid Piggyback | N2: Most Recent Proposal (Date) | O2: Job Release [BDM & DH] (Date) | P2: Engineering Release [BDM & Engineer] (Date) | Q2: Hand-off Meeting [BDM & PM] (Date) | R2: Kick-off Meeting [PM & ALL Depts] (Date) | S2: PM | T2: Estimated Value | U2: Estimated DSA Approval (per Engineering) | V2: Quarter | W2: Edited
A3: Romoland SD | B3: Boulder Ridge ES | C3: Diana | D3: 11642 | E3: 335647.68 | F3: (2) 24' x 40' classrooms | G3: 4 | H3: 46028 | I3: 45982 | J3: 1 | K3: To DSA by 9/1 | U3: Early October
A4: Mobile Modular | B4: Stock Classrooms | C4: Adela | D4: 11665 | E4: 7654077 | F4: (75) 24'x40' Classroom Buildings | G4: 150 | H4: 46034 | I4: 46113 | J4: 1 | K4: Revised proposal being presented to the customer | L4: PO- R320096701 | M4: Negotiated | N4: 45980
A5: Muroc Joint USD | B5: Boron HS | C5: Diana | D5: 11638 | E5: 276363.15 | F5: (1) 12x40 Restroom Model B-2 | G5: 1 | H5: 46043 | I5: 45962 | J5: 0.9 | K5: SCM generating CCD for adding the HVAC unit | L5: Executed Agreement received | M5: PB | N5: 45618 | O5: No | P5: No | T5: =IFERROR(E5*J5,0) -> 248726.84 | U5: Approved (Needs CCD for HVAC, assume mid October approval) | V5: =IFERROR(ROUNDUP(MONTH(IF(H5<>"",H5,""))/3, 0),"TBD") -> 1 | W5: =IF(I5<>"",IF(W5="",NOW(),W5),"") -> 45692.547
A6: Oceanside USD | B6: Jefferson MS | C6: Diana | D6: 11596 | E6: 5197374 | F6: (1) 84'x40' Kitchen (2) 96'x40' CR Bldgs. (1) 60'x40' Music Bldg. (2) 24'x40' RR Bldgs. | G6: 32 | H6: 46055 | I6: 46113 | J6: 1 | K6: Pending confirmation of options taken to finalize project pricing and scope. | L6: Yes | M6: Bid | N6: 45617 | O6: No | P6: No | T6: =IFERROR(E6*J6,0) -> 5197374 | U6: Late December | V6: =IFERROR(ROUNDUP(MONTH(IF(H6<>"",H6,""))/3, 0),"TBD") -> 1 | W6: =IF(I6<>"",IF(W6="",NOW(),W6),"") -> 45692.547
A7: Chula Vista USD | B7: Feaster School | C7: Diana | D7: 11636 | E7: 396510.73 | F7: (1) 48x40 | G7: 4 | H7: 46071 | U7: Late October
A8: Imperial County | B8: Little Bulldogs EHS | C8: Diana | D8: 11655 | E8: 754895 | F8: 48'x60' Daycare Kinder | G8: 4 | H8: 46077 | J8: 1 | K8: Finalizing price and project schedule to move forward. | L8: PO26-00973 | U8: NOT RELEASED TO ENGINEERING
A9: Action Day Schools | B9: Lincoln | C9: Joe | D9: 11630 | E9: 572840 | F9: (1) 36X40 Child Care Center | G9: 3 | H9: 46083 | I9: 46174 | J9: 1 | K9: Ryan to submit drawings for HCD review and approval. | L9: PO-6377 | M9: PB | N9: 45814 | O9: 45825 | P9: 45855 | Q9: 45852 | S9: Joe | T9: =IFERROR(E9*J9,0) -> 572840 | U9: HCD approval late December | W9: =IF(I9<>"",IF(W9="",NOW(),W9),"") -> 45692.547
A10: San Jacinto USD | B10: San Jacinto HS | C10: Diana | D10: 11618 | E10: 13511007 | F10: Two Story 170'/120' x 32' | G10: 58 | H10: 46086 | I10: 46327 | J10: 1 | K10: Contract is for 650 days from NTP. Project bids on 2/27/25. District is still reviewing paperwork for accuracy. Will send notification of SCM being the successful bidder after. As of 4/1 the district confirmed that they are still working with their legal team to put together the agreement before issuing us the NTP. | L10: C-1003868 | M10: Bid | N10: No | O10: No | P10: No | Q10: TBD | R10: TBD | U10: Mid December
A11: Menifee Union SD | B11: Ridgemoor ES | C11: Diana | D11: 11645 | E11: =267532.07+202011.77+636160.85 -> 1105704.7 | F11: (4) standard 24’ x 40’ classrooms, (1) 36'x40' Classroom (1) 12’ x 40’ restroom relocatable | G11: 12 | H11: 46093 | I11: 46178 | J11: 0.9 | K11: To DSA by 12/15 | M11: Bid | U11: NOT RELEASED TO ENGINEERING
A12: Keppel Union SD | B12: Pearblossom ES | C12: Sandra | D12: 11628 | E12: =871254/2 -> 435627 | F12: (3) 24'x40' Standard Classroom | G12: 6 | H12: 46094 | I12: 46006 | J12: 1 | K12: DSA app not till late July | L12: PO1-250000001456 | O12: No | S12: Joe | T12: =IFERROR(E12*J12,0) -> 435627 | U12: Late September | V12: =IFERROR(ROUNDUP(MONTH(IF(H12<>"",H12,""))/3, 0),"TBD") -> 1 | W12: =IF(I12<>"",IF(W12="",NOW(),W12),"") -> 45813.652
A13: South San Francisco USD | B13: Monte Verde ES | C13: Diana | D13: 11657 | E13: 887625.9 | F13: (1) 36'x40' Classroom with support rooms | G13: 3 | H13: 46105 | I13: 46174 | J13: 1 | K13: Customer taking to the board 10/6 | L13: Yes
A14: South San Francisco USD | B14: South San Francisco HS | C14: Diana | D14: 11640 | E14: 416593.32 | F14: (1) 24'x60' Office Building | G14: 2 | H14: 46107 | J14: 1 | K14: 8.7.25 District provided a LOI, will have signed proposal 8.24.2025 | L14: Yes | U14: Mid October
A15: South San Francisco USD | B15: Junipero Serra ES | C15: Diana | D15: 11656 | E15: 897625.9 | F15: (1) 36'x40' Classroom with support rooms | G15: 3 | H15: 46107 | I15: 46113 | J15: 1 | K15: In estimating | L15: Yes
A16: Ventura USD | B16: ATLAS School | C16: Diana | D16: 11594 | E16: 382738.04 | F16: (1) 12x60 Restroom | G16: 1 | H16: 46112 | I16: 46204 | J16: 1 | K16: DSA Approved. Per District, this project will be for Summer 2026. | L16: PO26-02865 | M16: PB | P16: Yes | Q16: 45861 | R16: TBD | S16: Joe | T16: =IFERROR(E16*J16,0) -> 382738.04 | U16: Approved | V16: =IFERROR(ROUNDUP(MONTH(IF(H16<>"",H16,""))/3, 0),"TBD") -> 1 | W16: =IF(I16<>"",IF(W16="",NOW(),W16),"") -> 45692.547
A17: Oaks Christian School | B17: Oaks Christian School | C17: Sandra | D17: 11672 | E17: 1999000 | F17: (12) 24x40 and (2) 12x40 RR | G17: 26 | H17: 46121 | J17: 0.5 | K17: DSA App 3/25/26
A18: Pasadena USD | B18: Franklin ES | C18: Sandra | D18: 11661 | E18: 8750000 | F18: Admin, Kitchen, MP | G18: 46 | H18: 46126 | I18: 45785 | J18: 1 | K18: Submitted Final Costs with Piggyback breakdowns and they are beginning to return them reviewed. | U18: Admin in Late Jan & MPR/Kitchen in Late Mar/Early Apr
A19: Pleasant Valley SD | B19: Valle Lindo ES (CAPE Charter School) | C19: Joe | D19: 11629 | E19: =234048+2515+9650 -> 246213 | F19: (1) 24x40 Office/Resource Building | G19: 2 | H19: 46133 | I19: 46174 | J19: 1 | K19: DSA appt 12/2/2025 | L19: PO 9001483 | M19: PB | N19: 45806 | O19: 45824 | P19: 45856 | Q19: 45852 | S19: Joe | T19: =IFERROR(E19*J19,0) -> 246213 | U19: Early December? (Does not appear that the AOR has a DSA appointment) | W19: =IF(I19<>"",IF(W19="",NOW(),W19),"") -> 45692.547
A20: Inglewood USD | B20: Oak St. Prep K- Phase 2 | C20: Sandra | D20: 11648 | E20: =335055.82+802544.94+1440973.64+1887030.71 -> 4465605.1 | F20: (1) 12x40 RR, (7) 36x40 Tk (3) 24x40 Classroom Bldg | G20: 28 | H20: 46141 | I20: 46235 | J20: 1 | K20: Balfour has requested breakdown of why cost went up so much | U20: Late December
A21: Corning Union ESD | B21: Community Day School (Columbia Academy) | C21: Diana | D21: 11660 | E21: 953588.47 | F21: (1) 72x40 Classroom Bldg | G21: 6 | H21: 46148 | I21: 46234 | J21: 0.8 | K21: LLB with United Building Contractors. District approved UBC in May 2025. Building production in Spring 2026. | T21: =IFERROR(E21*J21,0) -> 762870.78 | U21: Early April
A22: ABC USD | B22: Leal ES | C22: Sandra | D22: 11671 | E22: 305786 | F22: (2) 24x40 Classroom Bldgs | G22: 4 | H22: 46156 | J22: 1 | K22: DSA approved they are working on finalizing submittals
A23: Garvey SD | B23: Duff ES | C23: Sandra | D23: 11654 | E23: 803365.69 | F23: 60’x40’ Childcare Building | G23: 5 | H23: 46156 | J23: 1 | K23: In production | M23: Negotiated | U23: NOT RELEASED TO ENGINEERING
A24: Cerritos College | B24: Cerritos Community College | C24: Sandra | D24: 11643 | E24: 2389774.5 | F24: (2) 48x60 and (1) 24x60 TK Buildings | G24: 9 | H24: 46162 | I24: 46265 | J24: 1 | K24: Jonathan executed contract pending bonds and insurance PM working on change orders | L24: No | M24: PB | N24: 45616 | T24: =IFERROR(E24*J24,0) -> 2389774.5 | U24: February | W24: =IF(I24<>"",IF(W24="",NOW(),W24),"") -> 45692.547
A25: Mobile Modular | B25: Melrose | C25: Diana | D25: 11681 | E25: 139000 | F25: (1) 12x40 B2 RR | G25: 1 | H25: 46181
A26: Corning Union ESD | B26: Rancho Tehama ES | C26: Diana | D26: 11659 | E26: 673367.01 | F26: (1) 48'x40' Classrooms | G26: 4 | H26: 46182 | J26: 1 | K26: In DSA | U26: Early April
A27: San Diego USD | B27: SD Cooperative Charter School | C27: Diana | D27: 11644 | E27: 270248.43 | F27: (1) 36'x40' w/ single user RR | G27: 3 | H27: 46188 | I27: 46234 | J27: 0.5 | K27: The proposal was provided the customer is exploring their options due to budget. Might need to lease. | U27: NOT RELEASED TO ENGINEERING
A28: Rosemead USD | B28: Encinita ES | C28: Diana | D28: 11669 | E28: 187350.66 | F28: (1) 24'x40' Open Classroom | G28: 2 | H28: 46191 | J28: 0.9 | K28: Final proposal was sent to the AOR. Hand-off meeting to engineering took place. Waiting on confirmation on a few items from AOR for engineering to start drawings.
A29: Rescue USD | B29: Rescue ES | C29: Frank | D29: 11674 | E29: 169778.33 | F29: (1) 8.5x32 Restroom | G29: 1 | H29: 46195 | I29: 46239 | J29: 1 | K29: Drawings went to DSA for approval on 5/13
A30: Whittier City SD | B30: Jackson ES | C30: Sandra | D30: 11658 | E30: 389762.66 | F30: (1) 24x40 Double Classroom & (1) 12x40 RR | G30: 3 | H30: 46196 | J30: 1 | K30: In DSA | U30: NOT RELEASED TO ENGINEERING
A31: Fullerton SD | B31: Parks Junior High School | C31: Sandra | D31: 11647 | E31: 337086.71 | F31: (2) 24x40 Classroom Building | G31: 4 | H31: 46199 | K31: Pending DSA Approval | U31: NOT RELEASED TO ENGINEERING
A32: Palm Springs USD | B32: Two Bunch Palms ES | C32: Diana | D32: 11573 | E32: 112000 | F32: 8’-6”x16’-7” RR | G32: 1 | H32: 46204 | I32: 46235 | J32: 1 | K32: Project is moving forward, district working on a timeline. Back check appointment 4/8. | L32: No | M32: PB | N32: Pending Adel Release | O32: No | P32: No | R32: TBD | S32: Gino | T32: =IFERROR(E32*J32,0) -> 112000 | U32: Pending Schedule | V32: =IFERROR(ROUNDUP(MONTH(IF(H32<>"",H32,""))/3, 0),"TBD") -> 3 | W32: =IF(I32<>"",IF(W32="",NOW(),W32),"") -> 45692.547
A33: Unified Modular | B33: Unified Modular | C33: Diana | E33: TBD | F33: (1) 24'x40' Classroom Building w/RR and kitchenette | G33: 2 | H33: 46204 | I33: 46237 | J33: 0.1 | K33: Proposal went out 5/5/26 & is for Garvey.
A34: South Fork USD | B34: South Fork MS | C34: Frank | F34: (12) 24X40 Classroom Buildings | G34: =2*12 -> 24 | H34: 46204 | I34: 46266 | J34: 0.2 | K34: 5/14 Diana forwarded contact info and FC following up with customer | T34: =IFERROR('Leads, pre-con'!D7*J34,0) -> 177721.73 | U34: NOT RELEASED TO ENGINEERING
A35: Sunlife Corporate Housing | B35: Edwards AFB | C35: Frank | E35: 551515.38 | F35: (1) 60x40 Open Gym | G35: =5 -> 5 | H35: 46204 | I35: 45964 | J35: 0.3 | K35: 5/14 Diana forwarded contact info and FC following up with customer | M35: Bid | T35: =IFERROR(E35*J35,0) -> 165454.61 | U35: NOT RELEASED TO ENGINEERING
A36: La Habra USD | B36: La Dera ES | C36: Sandra | E36: 192714 | F36: (1) 12x40 TB | G36: 1 | H36: 46204 | J36: 1 | K36: Should receive PO week of 5/11/26; no later than 5/18/26
A37: Orange USD | B37: Panorama ES | C37: Sandra | D37: 11685 | E37: 362689.71 | F37: (2) 24x40 Buildings | G37: 4 | H37: 46204 | J37: 1 | K37: District working on purchase order
A38: MAOF/LAUSD Headstart | B38: Beta Vista Head Start | C38: Sandra | D38: 11679 | E38: 743643.93 | F38: (1) 40x60 Headstart Bldgs | G38: 6 | H38: 46204 | J38: 1 | K38: Received Signed Proposal to begin Drawings - PO to be issued in May | U38: NOT RELEASED TO ENGINEERING
A39: MAOF/LAUSD Headstart | B39: City Terrace Head Start | C39: Sandra | D39: 11680 | E39: 727753.87 | F39: (1) 40x52 Building | G39: 4 | H39: 46211 | J39: 1 | K39: Received Signed Proposal to begin Drawings - PO to be issued in May | U39: NOT RELEASED TO ENGINEERING
A40: Lowell SD | B40: Olita ES | C40: Sandra | D40: 11653 | E40: 1853773 | F40: 108x60 Classrooms w/RR | G40: 9 | H40: 46216 | J40: 1 | K40: In DSA | L40: PO W99B0031 | U40: NOT RELEASED TO ENGINEERING
...

Sheet ML Analysis
B2: Customer Name | C2: Project Name | D2: BDM | E2: Contract Value | F2: Building(s) | G2: Floor Count | H2: Start Date | I2: Current Status/Notes | J2: Lost Code | K2: Bid or Piggyback | L2: Lost to | M2: Enviroplex | N2: Class Leasing | O2: Mobile Modular | P2: AMS | Q2: GLOBAL | R2: SCM | S2: Var% to AMS | Y2: Customer Name | Z2: Lost Code
B3: Sierra Sands USD | C3: Murray MS | D3: Joe | F3: BUILDING C (1) 36X40 + (3) 30X32 BUILDING E (7) 30X32 | H3: 45658 | I3: Ryan to find out if we can meet bid due date | J3: Schedule | K3: PB | Y3: Sierra Sands USD | Z3: Schedule
B4: Ballico-Cressey SD | C4: Cressey ES | D4: Joe | E4: 3052557.5 | F4: (2) 72x40 TK (1) 12x40 RR | G4: 13 | I4: AMS $2,748,000 Global $2,854,000 SCM $3,052,557 | J4: Price | K4: PB | L4: AMS | P4: 2748000 | Q4: 2854000 | R4: 3052557 | S4: =(R4-P4)/P4 -> 0.1108286 | Y4: Ballico-Cressey SD | Z4: Price
B5: Victor Valley ESD | C5: Challenger ES | D5: Adela | E5: 382000 | F5: (1) 24x40 RR/Concession Bldg | I5: Timing, Pricing, Pass on location, Lost Funding, or went with Lease or Stick | J5: Price | Y5: Victor Valley ESD | Z5: Price
B6: Victor Valley ESD | C6: Lomitas ES | D6: Adela | E6: 260298 | F6: (1)24’x40 Restroom | I6: Over 80 deals we've looked at and didn't proceed with. | J6: Price | Y6: Victor Valley ESD | Z6: Price
B7: Tsumiki Preschool | C7: Tsumiki Preschool | D7: Diana | F7: (1) 36'x60' | I7: Cost of a new building was too much for the customer's budget | J7: price | Y7: Tsumiki Preschool | Z7: price
B8: Simi Valley | C8: Hillside MS | D8: Diana | E8: 291416.77 | F8: (2) 24'x40' | G8: 4 | H8: 45366 | I8: Schedule too tight to meet. | J8: Schedule | Y8: Simi Valley | Z8: Schedule
B9: La Mesa-Spring Valley | C9: Parkway Academy MS | D9: Diana | F9: (1) 24'x40' | I9: Cost of a new building was too much for the customer's budget | J9: Funding | Y9: La Mesa-Spring Valley | Z9: Funding
B10: Jefferson SD | C10: Corral Hollow ES | D10: Joe | E10: 2990052.7 | F10: BUILDING A (1) 36x40 TK BUILDING B (1) 108x40 TK BUILDING C (1) 36x40 TK BUILDING D (1) 108x40 PE CR | G10: 24 | I10: District does not have the funding to move forward per PJHM | J10: Funding | K10: PB | Y10: Jefferson SD | Z10: Funding
B11: Merced City SD | C11: Franklin ES | D11: Joe | E11: 6826236 | F11: WING A (1) 196X40 WING B (1) 160X40 | G11: 29 | H11: 45748 | I11: 1. AMS $5,948,000.00 ($878K below SCM) 2. Global $6,546,000.00 ($280K below SCM) 3. Silver Creek $6,826,236.00 | J11: Price | K11: Bid | L11: AMS | P11: 5948000 | Q11: 6546000 | R11: 6826236 | S11: =(R11-P11)/P11 -> 0.14765232 | Y11: Merced City SD | Z11: Price
B12: Bishop USD | C12: MOT Yard | D12: Joe | E12: 878824.03 | F12: (1) 72X40 Office Bldg | G12: 6 | H12: TBD | I12: Our price is too high. District expoloring other options | J12: Price | K12: PB | Y12: Bishop USD | Z12: Price
B13: Sylvan USD | C13: Somerset MS | D13: Joe | E13: 461894.85 | F13: (1) 60x40 Childcare | G13: 5 | H13: 45566 | I13: Lost deal to AMS $415,287.00 | J13: Price | K13: PB | L13: AMS | P13: 415287 | R13: 461894.85 | S13: =(R13-P13)/P13 -> 0.11223046 | Y13: Sylvan USD | Z13: Price
B14: Downey USD | C14: Downey USD | D14: Adela | F14: (13) TK Classrooms | I14: Pricing too high | J14: Price | K14: PB | Y14: Downey USD | Z14: Price
B15: Hemet USD | C15: Hemet HS | D15: Adela-Sandra | E15: 570182.81 | F15: (4) 24x40 | G15: 8 | H15: TBD | I15: Lost to Competitor | J15: Price | K15: PB | Y15: Hemet USD | Z15: Price
B16: Orange USD | D16: Adela-Sandra | E16: 257193 | F16: (2) 24X40 | G16: 4 | H16: TBD | I16: Lost to Competitor | J16: Price | K16: PB | Y16: Orange USD | Z16: Price
B17: Academy for Advancement of Children with Autism | C17: AACA | D17: Adela-Sandra | E17: 584811.41 | F17: 96x60 Classroom | G17: 8 | H17: TBD | I17: Lost to Competitor | J17: Price | K17: PB | Y17: Academy for Advancement of Children with Autism | Z17: Price
B18: South San Francisco USD | C18: Los Cerritos ES | D18: Joe | E18: 157240.21 | F18: (1) 12x40 RR | G18: 1 | H18: 45597 | I18: Project will go out to bid. | J18: Price | K18: PB | Y18: South San Francisco USD | Z18: Price
B19: ASYMCA | C19: ASYMCA | D19: Diana | E19: 1915724.6 | F19: (2) 60'x60 CR Bldgs. | G19: 12 | H19: 45580 | I19: Customer had concerns with SCM's pricing after all the finishes were upgraded. They moved on and procure the buildings from Phoenix Modular. | J19: Price | K19: PB | L19: Phoenix Modular | Y19: ASYMCA | Z19: Price
B20: San Jacinto USD | C20: Facilities & Operations | D20: Adela-Sandra | E20: 2884615 | F20: (1) 144'x48' | G20: 12 | H20: 45778 | I20: On hold | J20: MISC | K20: PB | Y20: San Jacinto USD | Z20: MISC
B21: Blok Modular | C21: Las Palmas | D21: Diana | F21: (1) 12'x40', (1) 12'x24', (1) 12'x50', (1) 12'x40' RR Bldgs. | G21: 5 | H21: TBD | I21: SCM pricing was 30% higher than our competitors, per Blok's owner. | J21: Price | K21: PB | S21: 0.3 | Y21: Blok Modular | Z21: Price
B22: Fall River JUSD | C22: Fall River ES | D22: Joe | F22: (4) 24x40 2:12 PC Classrooms | G22: 8 | H22: 45658 | I22: 8/20 Per Steve, proceed with estimating 8/21 submitted to estimating SCM to outsource delivery, installation and service to DVMB. Our pricing is three times the District's budget. | J22: MISC | K22: PB | Y22: Fall River JUSD | Z22: MISC
B23: Marysville JUSD | C23: Arboga ES | D23: Joe | E23: 260240.33 | F23: (1) 40X32 | G23: 4 | H23: 45627 | I23: Lost to Mobile Modular $209,597 | J23: price | K23: Bid | O23: 209597 | R23: 260240.33 | Y23: Marysville JUSD | Z23: price
B24: Cajon Valley USD | C24: Johnson ES | D24: Diana | F24: (1) 24'x40' Classroom | G24: 2 | H24: 45778 | I24: Lost deal to AMS per the district we were higher. SCM provided a list of why our buidlings are more expensive than AMS. | J24: price | K24: PB | L24: AMS | Y24: Cajon Valley USD | Z24: price
B25: Cajon Valley USD | C25: Avocado ES | D25: Diana | F25: (3) 30'X32' Classrooms | G25: 9 | H25: 45778 | I25: Lost deal to AMS per the district we were higher. SCM provided a list of why our buidlings are more expensive than AMS. | J25: price | K25: PB | L25: AMS | Y25: Cajon Valley USD | Z25: price
B26: Waterford USD | C26: Moon PS | D26: Joe | E26: 5166484 | F26: (2) 144x40 TK Bldgs | G26: 24 | H26: 46113 | I26: Low Bidder: Global $4,440,000 $385/SF ($726,484) AMS $4,498,000 $390/SF ($668,484) SCM $5,166,484 $448/SF | J26: price | K26: Bid | L26: Global | P26: 4498000 | Q26: 4440000 | R26: 5166484 | S26: =(R26-P26)/P26 -> 0.14861805 | Y26: Waterford USD | Z26: price
B27: Arcadia USD | F27: (10) 24x40 | G27: 20 | H27: 45809 | Y27: Arcadia USD
B28: San Rafael City Schools | C28: Terra Linda HS | D28: Adela-Sandra | E28: 644754.52 | F28: 24x40 Concession/RR 8-6x21-6 Storage/Ticket | G28: 3 | H28: TBD | I28: Customer was notified that SCM could not proceed with project if they required us to meet project bid manual | K28: GC | Y28: San Rafael City Schools
B29: PMSI - Michael Thompson | C29: 36'x48' | D29: Diana | E29: 206387.63 | F29: 36'x48' HCD building | G29: 3 | H29: TBD | I29: Lost deal due to pricing. | J29: price | Y29: PMSI - Michael Thompson | Z29: price
B30: Cal State Long Beach | C30: Cal State Long Beach | D30: Sandra | F30: (1) 12x40 TB | G30: 1 | I30: Customer has decided to lease bldg | J30: MISC | Y30: Cal State Long Beach | Z30: MISC
B31: Irvine Community College | C31: Irvine Community College | D31: Sandra | F31: (1) 48x40 Locker Room | G31: 4 | H31: TBD | I31: Bought a used building | J31: MISC | Y31: Irvine Community College | Z31: MISC
B32: LAUSD- Irving Steam Magnet | D32: Adela-Sandra | E32: 0 | F32: 72x40 | G32: 6 | H32: 45748 | I32: Provided Quote 10/14/24 | Y32: LAUSD- Irving Steam Magnet
B33: Hueneme ESD | C33: Larsen ES & Hollywood ES | D33: Diana | E33: 0 | F33: (6) 72'x40' TK Buildings | G33: 36 | H33: 45748 | I33: SCM agreed to not bid. Bid Results are as follows: Class Leasing $2,434,693.00 ($140.896) , NextMod $2,736,417.84 ($158.3575), Global Modular $3,398,500.00 ($196.672) SF. total: 17,280 | J33: MISC | Y33: Hueneme ESD | Z33: MISC
B34: Blok Modular | C34: Fort Irwin | D34: Diana | F34: (1) 12'x24' DOH | G34: 1 | H34: TBD | I34: SCM pricing was too high | J34: Price | Y34: Blok Modular | Z34: Price
B35: SDUSD | C35: Hardy ES | D35: Diana | F35: (4) 36'x40 CRs w/ RRs, (6) 24'x40' Open CRs, (1) 12'x40' RR | G35: 25 | H35: 2026 | I35: SCM pricing was too high | J35: Price | K35: 2026 | Y35: SDUSD | Z35: Price
B36: Cypress College | D36: Sandra | E36: 365832.45 | F36: 24x40 Bldg | G36: 2 | H36: TBD | I36: Lost due to timeline | J36: Schedule | Y36: Cypress College | Z36: Schedule
B37: Unified Modular | C37: Montebello USD | D37: Diana | F37: (1) 24'X40' CR | G37: 2 | H37: N/A | I37: Customer submitted proposal pending board approval. Project not awarded to our customer | J37: Funding | Y37: Unified Modular | Z37: Funding
B38: San Mateo County Community College District | C38: Cañada College | D38: Joe | E38: 5000000 | F38: (1) 107X37 Building A (1) 120x37 Building B | G38: 17 | H38: 45839 | I38: No bid per Dennis and Ryan. Unable to provide a Cross Laminated Mass Timer (CLT) modular building per bid specs. | J38: Technical | K38: 46023 | Y38: San Mateo County Community College District | Z38: Technical
B39: Bush Construction | C39: Firebaugh-Las Deltas USD Bailey PS | D39: Joe | E39: 6388910.2 | F39: (1) 24x40 Office Building (7) 72x40 TK | G39: 44 | H39: 45901 | I39: Class Leasing - 1st place $5.7M $287/SF 145/145 Best Value Scoring SCM - 2nd place $6.3M $370/SF 109/145 Best Value Scoring Enviroplex - 3rd place $8.8M $438/SF 82/145 Best Value Scoring | J39: Price | K39: PB | L39: Class Leasing | M39: 8800000 | N39: 5700000 | R39: 6300000 | Y39: Bush Construction | Z39: Price
B40: DV Modular | C40: DV Modular | D40: Diana | F40: (1) 24'x60' Open Building | G40: 2 | I40: SCM pricing was too high compared to SF pricing dealer had submitted to their customer | J40: Price | K40: PB | Y40: DV Modular | Z40: Price
B41: Fairfax SD | C41: District Office | D41: Joe | E41: 7000000 | F41: (1) 200X60 Admin Bldg | G41: 30 | H41: 46023 | I41: no bid, building not modular friendly. 27' high | J41: Technical | K41: Winter 2025 | Y41: Fairfax SD | Z41: Technical
...

Sheet Sales Summary Report
B2: Revenue by Quarter | C2: 153459650 | D2: 129681327 | H2: Project by Highest Contract Value
B3: Row Labels | C3: Sum of Contract | D3: Sum of Estimated Value | E3: # of Projects | F3: Sum of Floor(s) | H3: Contract Value | I3: Project Name | J3: PM
B4: 1 | C4: 41948855 | D4: 30764797 | E4: 31 | F4: 298 | H4: 12835820 | I4: Mare Island Technology Academy | J4: Lori
B5: 2 | C5: 32932478 | D5: 32852017 | E5: 34 | F5: 225 | H5: 11797264 | I5: Surfside | J5: Kenny
B6: 3 | C6: 41001710 | D6: 40791530 | E6: 11 | F6: 185 | H6: 8000000 | I6: Marshall ES | J6: (blank)
B7: 4 | C7: 36278842 | D7: 26470050 | E7: 27 | F7: 229 | H7: 5766106.2 | I7: Parkview School TK-8 | J7: Moanes
B8: TBD | C8: 3931270.7 | D8: 272710 | E8: 15 | F8: 62 | H8: 5697280 | I8: Health Center | J8: (blank)
B9: (blank) | C9: 73369068 | D9: 17208899 | E9: 80 | F9: 506 | H9: 5159577.8 | I9: Jefferson MS | J9: Kenny
B10: Grand Total | C10: 2.2946222e+08 | D10: 1.4836e+08 | E10: 198 | F10: 1505 | H10: 4494585.5 | I10: Monterey Vista ES | J10: (blank)
B11: Revenue by BDM | H11: 3153674.9 | I11: Arcadia HS | J11: (blank)
B12: Row Labels | C12: Sum of Estimated Value | H12: 3006336.8 | I12: Vineland ES | J12: Lori
B13: Diana | C13: 27942871 | H13: 2970266.2 | I13: Wasco HS | J13: Lori
B14: Diana/Quinton | C14: 125464.19 | H14: 2885231.4 | I14: Oak Meadows ES | J14: (blank)
B15: Joe | C15: 31855842 | H15: 2816398 | I15: Harding ES | J15: Kenny
B16: Quinton/Diana | C16: 249912.61 | H16: 2740000 | I16: Hans Christensen ES | J16: Kenny
B17: Sandra | C17: 89882583 | H17: 2532016.4 | I17: Rancho Starbuck Intermediate | J17: Moanes
B18: (blank) | C18: 0 | H18: 2467455.7 | I18: Freedom Crest ES | J18: (blank)
B19: Grand Total | C19: 1.5005667e+08 | H19: 2448024.2 | I19: Torrance ES | J19: Moanes
H20: 2392640.9 | I20: Carr ES | J20: Moanes
B21: Pipeline Distribution by PM | H21: 2137747.9 | I21: Callie Kirkpatrick ES | J21: (blank)
B22: Row Labels | C22: Sum of Estimated Value | D22: # of Projects | H22: 2123331.7 | I22: New Phelan ES | J22: (blank)
B23: Gino | C23: 21511074 | D23: 36 | H23: 2105834.8 | I23: Cerritos Community College | J23: (blank)
B24: Kenny | C24: 26412531 | D24: 10 | H24: 2028742 | I24: District Office | J24: (blank)
B25: Lori | C25: 21042883 | D25: 8 | H25: 2000000 | I25: Calistoga ES | J25: (blank)
B26: Mehdi | C26: 20036800 | D26: 1 | H26: 1998719.7 | I26: Oak St. Prep K | J26: Moanes
B27: Moanes | C27: 25083318 | D27: 25 | H27: 1927490 | I27: Helendale ES | J27: (blank)
B28: TBD | C28: 417361.4 | D28: 2 | H28: 1870996.9 | I28: New Phelan ES | J28: (blank)
B29: (blank) | C29: 35552706 | D29: 86 | H29: 1852667.4 | I29: Arcadia HS | J29: (blank)
B30: Grand Total | C30: 1.5005667e+08 | D30: 168 | H30: 1848439.6 | I30: Fremont ES - iHigh Virtual Academy | J30: Kenny
H31: 1801375 | I31: El Portal ES | J31: Moanes
H32: 1573755 | I32: Only Love Children's Center #4 | J32: (blank)
H33: 1565922.8 | I33: Colton | J33: Gino
H34: 1444491.4 | I34: Sandia Academy | J34: Gino
I35: Yucca Loma ES | J35: Gino
B36: Detailed Job by Quarter | H36: 1420634.9 | I36: Beaumont Adult School | J36: Gino
B37: Quarter | C37: Project Name | D37: Sum of Contract | E37: Sum of Estimated Value | F37: Sum of Floor(s) | H37: 1414508.7 | I37: Quail Valley ES | J37: (blank)
B38: 1 | C38: Health Center | D38: 5697280 | E38: 4272960 | F38: 24 | H38: 1387218.6 | I38: Peter Marshall ES | J38: Moanes
C39: Arcadia HS | D39: 5006342.3 | E39: 2503171.1 | F39: 21 | H39: 1381085.5 | I39: Various Sites | J39: Kenny
C40: Beaumont Adult School | D40: 1420634.9 | E40: 1420634.9 | F40: 12 | H40: 1304554.6 | I40: Farragut ES | J40: (blank)
C41: Beyer HS | D41: 246171.81 | E41: 246171.81 | F41: 1 | H41: 1240813.2 | I41: New Phelan ES | J41: (blank)
...

Sheet Leads, pre-con
A1: Customer | B1: Project Name | C1: BDM | D1: Contract Value | E1: Building(s) | F1: Floor(s) | G1: Start Date for Production | H1: Confidence Level | I1: Current Status/Notes
A2: Asher University | B2: Asher University | C2: Sandra | E2: (2) 168X40 Classroom and Admin Office | F2: 56 | H2: 0.2 | I2: Customer aquired property working on funding. Still waiting on city to approve new roads to site
A3: Endovate Charter School | B3: Endovate Charter School | C3: Sandra | E3: (5) 36x20 Classroms and (1) 12x40TB | F3: 15 | H3: 0.25 | I3: Provided them information to submit for their board to review they are finalizing whether they will proceed with current floorplans or change.
A4: Hope Academy | C4: Sandra | E4: TK | F4: 12 | G4: 46235 | H4: 0.1 | I4: Followed up with customer and they are redesigning their site in hopes of saving some money
A5: Santa Moncia Malibu USD | B5: Middle School | C5: Sandra | E5: Two Story (2) 96’x40’ | F5: 1 | I5: Adela still meeting with customer to review
A6: LA Community College District | B6: ELAC South Gate | C6: Sandra | D6: 473556.18 | E6: 24x40 RR/Concession | F6: 2 | H6: 0.2 | I6: Waiting for funding
A7: LA Community College District | B7: East LA College Shop Bldg | C7: Sandra | D7: 888608.67 | E7: (4) 24x40 | F7: 8 | H7: 0.2 | I7: No Start Date/Waiting on Funding
A8: Savannah SD | B8: Cypress King ES | C8: Sandra | D8: =145075.18+190722.58+190573.12 -> 526370.88 | E8: (2)24’x40’ Office and (1) 12x40 | F8: 5 | G8: 46230 | H8: 0.2 | I8: Architect submitted Soils report for Ryans review. She would like him to design the foundation
A9: Chula Vista USD | B9: Fahari Jeffers | C9: Diana | F9: 108'x40' Two Story | K9: No update | U9: NOT RELEASED TO ENGINEERING
A10: Corcoran Police Station | C10: Diana | K10: 8.7.2025 Customer waiting for a proposal | L10: No | M10: Bid | N10: No | O10: No | P10: No | T10: =IFERROR(E10*J10,0) -> 0 | U10: NOT RELEASED TO ENGINEERING | V10: =IFERROR(ROUNDUP(MONTH(IF(H10<>"",H10,""))/3, 0),"TBD") -> TBD | W10: =IF(I10<>"",IF(W10="",NOW(),W10),"")

Sheet 2 Week Look-Ahead
A2: 2 WEEK LOOK-AHEAD
A5: WE | B5: JOB # | C5: PROJECT | D5: BUILDING | E5: WEEK OF JULY 7 | F5: WEEK OF JULY 14 | G5: DSA Date | H5: COMMENTS
A6: Diana Tavarez
A7: 1 | C7: Tehama Department of Education | D7: (1) 36'x40' | H7: No ETA. Waiting on revised floor plan
A8: 2 | C8: Redlands USD Model C-2 RR | D8: (1) 12'x40' Restroom | G8: 46196
A9: 3 | C9: Charles White Park | D9: (1) 64'x79' | H9: In progress
A10: 4 | C10: SDUSD Jerabek ES | D10: (4) 24'x40'classrooms, (1) 12'x40' Restroom | G10: 46178 | H10: AOR is reviewing our PC's and is to provide updates.
C11: Beaumont USD - (4) Sites | D11: 24'x40's and 32' RRs | G11: 46235
B12: Sandra Adame
A13: 5 | C13: Orange USD | D13: (2) 24x40 Classroom Bldgs with RR | H13: Wtg on PO
A14: 6 | C14: Oxnard SD-Freemont MS | D14: (2) 36x40 Lockerroom Buildings | H14: Ryan, Adela, and I met with customer.
A15: 7 | C15: ABC USD- Niemes ES | D15: 60x40 | H15: Proposal in review w/customer
B16: Frank Carrillo
A17: 8 | C17: Folsom Cordova USD - Granite Springs ES | D17: (1) 144x40, (1) 156x40 & (1) 48x40 | H17: Kickoff scheduled for Monday 5/18

Sheet Lost Deals
A1: Lost Code | B1: Customer Name | C1: Project Name | D1: BDM | E1: Contract Value | F1: Building(s) | G1: Floor Count | H1: Start Date | I1: Current Status/Notes | J1: Bid or Piggyback | K1: Estimated Project Completion | L1: Confidence Level | M1: Estimated Value
A2: Schedule | B2: Sierra Sands USD | C2: Murray MS | D2: Joe | F2: BUILDING C (1) 36X40 + (3) 30X32 BUILDING E (7) 30X32 | H2: 45658 | I2: Ryan to find out if we can meet bid due date | J2: Bid | K2: Summer 2025 | L2: 0.3 | M2: =E2*L2 -> 0
A3: Price | B3: Ballico-Cressey SD | C3: Cressey ES | D3: Joe | E3: 3052557.5 | F3: (2) 72x40 TK (1) 12x40 RR | G3: 13 | I3: AMS $2,748,000 Global $2,854,000 SCM $3,052,557 | J3: Bid | K3: Summer 2025 | L3: 0 | M3: =E3*L3 -> 0
A4: Price | B4: Victor Valley ESD | C4: Challenger ES | D4: Adela | E4: 382000 | F4: (1) 24x40 RR/Concession Bldg | I4: Timing, Pricing, Pass on location, Lost Funding, or went with Lease or Stick
A5: Price | B5: Victor Valley ESD | C5: Lomitas ES | D5: Adela | E5: $260.298.00 | F5: (1)24’x40 Restroom | I5: Over 80 deals we've looked at and didn't proceed with.
A6: Price | B6: Tsumiki Preschool | C6: Tsumiki Preschool | D6: Diana | E6: 390038.78 | F6: (1) 36'x60' | I6: Cost of a new building was too much for the customer's budget
A7: Schedule | B7: Simi Valley | C7: Hillside MS | D7: Diana | E7: 291416.77 | F7: (2) 24'x40' | G7: 4 | H7: 45366 | I7: Schedule too tight to meet.
A8: Funding | B8: La Mesa-Spring Valley | C8: Parkway Academy MS | D8: Diana | E8: 138449 | F8: (1) 24'x40' | G8: 4 | I8: Cost of a new building was too much for the customer's budget
A9: Funding | B9: Jefferson SD | C9: Corral Hollow ES | D9: Joe | E9: 2990052.7 | F9: BUILDING A (1) 36x40 TK BUILDING B (1) 108x40 TK BUILDING C (1) 36x40 TK BUILDING D (1) 108x40 PE CR | G9: 24 | I9: District does not have the funding to move forward per PJHM | J9: PB | K9: Summer 2025 | L9: 0 | M9: =E9*L9 -> 0
A10: Price | B10: Merced City SD | C10: Franklin ES | D10: Joe | E10: 6826236 | F10: WING A (1) 196X40 WING B (1) 160X40 | G10: 29 | H10: 45748 | I10: 1. AMS $5,948,000.00 ($878K below SCM) 2. Global $6,546,000.00 ($280K below SCM) 3. Silver Creek $6,826,236.00 | J10: Bid | K10: Fall 2025 | L10: 0 | M10: =E10*L10 -> 0
A11: Price | B11: Bishop USD | C11: MOT Yard | D11: Joe | E11: 878824.03 | F11: (1) 72X40 Office Bldg | G11: 6 | H11: TBD | I11: Our price is too high. District expoloring other options | J11: PB | K11: Summer 2025 | L11: 0 | M11: =E11*L11 -> 0
A12: Price | B12: Sylvan USD | C12: Somerset MS | D12: Joe | E12: 461894.85 | F12: (1) 60x40 Childcare | G12: 5 | H12: 45566 | I12: Lost deal to AMS $415,287.00 | J12: PB | K12: Summer 2025 | L12: 0 | M12: =E12*L12 -> 0
A13: Price | B13: Downey USD | C13: Downey USD | D13: Adela | F13: (13) TK Classrooms | I13: Pricing too high
A14: Price | B14: Hemet USD | C14: Hemet HS | D14: Adela-Sandra | E14: 570182.81 | F14: (4) 24x40 | G14: 8 | H14: TBD | I14: Lost to Competitor | J14: PB | K14: N/A | L14: 0.05
A15: Price | B15: Orange USD | D15: Adela-Sandra | E15: 257193 | F15: (2) 24X40 | G15: 4 | H15: TBD | I15: Lost to Competitor | J15: PB | K15: N/A | L15: 0.25
A16: Price | B16: Academy for Advancement of Children with Autism | C16: AACA | D16: Adela-Sandra | E16: 584811.41 | F16: 96x60 Classroom | G16: 8 | H16: TBD | I16: Lost to Competitor | J16: PB | K16: N/A | L16: 0.5
A17: Other | B17: South San Francisco USD | C17: Los Cerritos ES | D17: Joe | E17: 157240.21 | F17: (1) 12x40 RR | G17: 1 | H17: 45597 | I17: Project will go out to bid. | K17: PB | L17: No
A18: Other | B18: ASYMCA | C18: ASYMCA | D18: Diana | E18: 1915724.6 | F18: (2) 60'x60 CR Bldgs. | G18: 12 | H18: 45580 | I18: Customer had concerns with SCM's pricing after all the finishes were upgraded. They moved on and procure the buildings from Phoenix Modular. | K18: Negotiated
B19: San Jacinto USD | C19: Facilities & Operations | D19: Adela-Sandra | E19: 2884615 | F19: (1) 144'x48' | G19: 12 | H19: 45778 | I19: On hold | J19: PB | K19: TBD | L19: =E19*A19 -> 0
A20: Price | B20: Blok Modular | C20: Las Palmas | D20: Diana | E20: 1004331.7 | F20: (1) 12'x40', (1) 12'x24', (1) 12'x50', (1) 12'x40' RR Bldgs. | G20: 5 | H20: TBD | I20: SCM pricing was 30% higher than our competitors, per Blok's owner.
A21: Price | B21: Fall River JUSD | C21: Fall River ES | D21: Joe | E21: 1452611.5 | F21: (4) 24x40 2:12 PC Classrooms | G21: =4*2 -> 8 | H21: 45658 | I21: 8/20 Per Steve, proceed with estimating 8/21 submitted to estimating SCM to outsource delivery, installation and service to DVMB. Our pricing is three times the District's budget. | J21: PB | K21: 45838 | L21: =E21*A21 -> #VALUE!
A22: Price | B22: Marysville JUSD | C22: Arboga ES | D22: Joe | E22: 260240.33 | F22: (1) 40X32 | G22: 4 | H22: 45627 | I22: Lost to Mobile Modular $209,597 | J22: Bid | K22: End 2024 | L22: =E22*A22 -> #VALUE!
A23: Price | B23: Cajon Valley USD | C23: Johnson ES | D23: Diana | E23: 132747 | F23: (1) 24'x40' Classroom | G23: 2 | H23: 45778 | I23: Lost deal to AMS per the district we were higher. SCM provided a list of why our buidlings are more expensive than AMS. | J23: PB | K23: Summer 2025
A24: Price | B24: Cajon Valley USD | C24: Avocado ES | D24: Diana | E24: 414860 | F24: (3) 30'X32' Classrooms | G24: 9 | H24: 45778 | I24: Lost deal to AMS per the district we were higher. SCM provided a list of why our buidlings are more expensive than AMS. | J24: PB | K24: Summer 2025
A25: Price | B25: Waterford USD | C25: Moon PS | D25: Joe | E25: 5166484 | F25: (2) 144x40 TK Bldgs | G25: 24 | H25: 46113 | I25: Low Bidder: Global $4,440,000 $385/SF ($726,484) AMS $4,498,000 $390/SF ($668,484) SCM $5,166,484 $448/SF | J25: Bid | K25: Summer 2026 | L25: =E25*A25 -> #VALUE! | M25: TBD
A26: Other | B26: Arcadia USD | E26: No BOM | F26: (10) 24x40 | G26: 20 | H26: 45809 | I26: Only showing ISS for Crs, no BOM for CR buildings | M26: TBD
A27: Other | B27: San Rafael City Schools | C27: Terra Linda HS | D27: Adela-Sandra | E27: =504039.5+140715.02 -> 644754.52 | F27: 24x40 Concession/RR 8-6x21-6 Storage/Ticket | G27: 3 | H27: TBD | I27: Customer was notified that SCM could not proceed with project if they required us to meet project bid manual | J27: GC | K27: Summer 2024 | L27: =E27*A27 -> #VALUE!
A28: Price | B28: PMSI - Michael Thompson | C28: 36'x48' | D28: Diana | E28: 206387.63 | F28: 36'x48' HCD building | G28: 3 | H28: TBD | I28: Lost deal due to pricing.
A29: Price | B29: Cal State Long Beach | C29: Cal State Long Beach | D29: Sandra | E29: No BOM | F29: (1) 12x40 TB | G29: 1 | I29: Customer has decided to lease bldg
A30: Other | B30: Irvine Community College | C30: Irvine Community College | D30: Sandra | E30: No BOM | F30: (1) 48x40 Locker Room | G30: 4 | H30: TBD | I30: Bought a used building
A31: Price | B31: LAUSD- Irving Steam Magnet | D31: Adela-Sandra | E31: 0 | F31: 72x40 | G31: 6 | H31: 45748 | I31: Provided Quote 10/14/24
A32: Other | B32: Hueneme ESD | C32: Larsen ES & Hollywood ES | D32: Diana | E32: 0 | F32: (6) 72'x40' TK Buildings | G32: 36 | H32: 45748 | I32: SCM agreed to not bid. Bid Results are as follows: Class Leasing $2,434,693.00 ($140.896) , NextMod $2,736,417.84 ($158.3575), Global Modular $3,398,500.00 ($196.672) SF. total: 17,280
A33: Price | B33: Blok Modular | C33: Fort Irwin | D33: Diana | E33: 111382 | F33: (1) 12'x24' DOH | G33: 1 | H33: TBD | I33: SCM pricing was too high
A34: Price | B34: SDUSD | C34: Hardy ES | D34: Diana | E34: 1900832 | F34: (4) 36'x40 CRs w/ RRs, (6) 24'x40' Open CRs, (1) 12'x40' RR | G34: 25 | H34: 2026 | I34: SCM pricing was too high | J34: 2026 | K34: N/A
A35: Schedule | B35: Cypress College | D35: Sandra | E35: 365832.45 | F35: 24x40 Bldg | G35: 2 | H35: TBD | I35: Lost due to timeline
A36: Other | B36: Unified Modular | C36: Montebello USD | D36: Diana | E36: 241705 | F36: (1) 24'X40' CR | G36: 2 | H36: N/A | I36: Customer submitted proposal pending board approval. Project not awarded to our customer
A37: Other | B37: San Mateo County Community College District | C37: Cañada College | D37: Joe | E37: 5000000 | F37: (1) 107X37 Building A (1) 120x37 Building B | G37: =8+9 -> 17 | H37: 45839 | I37: No bid per Dennis and Ryan. Unable to provide a Cross Laminated Mass Timer (CLT) modular building per bid specs. | J37: 46023 | K37: Bid
A38: Price | B38: Bush Construction | C38: Firebaugh-Las Deltas USD Bailey PS | D38: Joe | E38: 6388910.2 | F38: (1) 24x40 Office Building (7) 72x40 TK | G38: 44 | H38: 45901 | I38: Class Leasing - 1st place $5.7M $287/SF 145/145 Best Value Scoring SCM - 2nd place $6.3M $370/SF 109/145 Best Value Scoring Enviroplex - 3rd place $8.8M $438/SF 82/145 Best Value Scoring | J38: Fall 2026 | K38: 45600 | L38: TBD
A39: Price | B39: DV Modular | C39: DV Modular | D39: Diana | E39: 293614 | F39: (1) 24'x60' Open Building | G39: 2 | I39: SCM pricing was too high compared to SF pricing dealer had submitted to their customer
A40: Other | B40: Fairfax SD | C40: District Office | D40: Joe | E40: 7000000 | F40: (1) 200X60 Admin Bldg | G40: 30 | H40: 46023 | I40: no bid, building not modular friendly. 27' high | J40: Winter 2025 | K40: No | L40: TBD
...

Sheet Sheet3
A3: Lost Code | B3: Count of Customer Name
A4: Funding | B4: 7
A5: MISC | B5: 23
A6: Pre-qual | B6: 1
A7: Price | B7: 46
A8: Schedule | B8: 9
A9: Technical | B9: 5
A10: (blank) | B10: 6

Sheet Closed Deals 23 & 24
A1: Customer | B1: Project Name | C1: BDM | D1: Job Number | E1: Contract Value | F1: Building(s) | G1: Floor(s) | H1: Start Date for Production | I1: Estimated DSA Approval (per Engineering) | J1: Contract Type | K1: Current Status/Notes | L1: Confidence Level | M1: Bid Piggyback | N1: Estimated Completion Date | O1: Most Recent Proposal (Date) | P1: Engineering Release (Date) | Q1: Job Release (Date) | R1: PM | S1: Estimated Value | T1: Kick-off Meeting | U1: Hand-off Meeting
A2: Magnolia SD | B2: Dr. Albert Schweitzer 60x32 | C2: Sandra | D2: 11443 | E2: 632019.37 | F2: 60x32 | G2: 5 | H2: 45163 | I2: Approved | J2: PO | K2: N/A | L2: 1 | M2: PB | N2: August, 2024 | P2: Yes | Q2: Yes | R2: Moanes | S2: =IFERROR(E2*L2,0) -> 632019.37
A3: Modesto CS | B3: El Vista ES | C3: Joe | D3: 11446 | E3: 5500000 | F3: (1) 156X60 MPR/Cafeteria | G3: 26 | H3: 45163 | I3: Approved | J3: Signed Proposal | K3: N/A | L3: 1 | M3: PB | N3: 45474 | O3: Yes | P3: Yes | Q3: Yes | R3: Kenny | S3: =IFERROR(E3*L3,0) -> 5500000
A4: Mountain View SD | B4: Miramonte ES | C4: Sandra | D4: 11403 | E4: 181837 | F4: 12x40 Restroom | G4: 1 | H4: 45180 | I4: Approved | J4: PO | K4: N/A | L4: 1 | M4: PB | N4: November/December,2023 | P4: Yes | Q4: Yes | R4: Gino | S4: =IFERROR(E4*L4,0) -> 181837
A5: Mountain View SD | B5: Monte Vista ES | C5: Sandra | D5: 11401 | E5: 181837 | F5: 12x40 Restroom | G5: 1 | H5: 45181 | I5: Approved | J5: PO | K5: N/A | L5: 1 | N5: November/December,2023 | P5: Yes | Q5: Yes | R5: Gino | S5: =IFERROR(E5*L5,0) -> 181837
A6: Coachella USD | B6: North Shore ES | C6: Sandra | D6: 11397 | E6: 13916167 | F6: New Campus | G6: 83 | H6: 45187 | I6: Approved | J6: Contract | K6: N/A | L6: 1 | M6: PB | N6: September, 2024 | P6: Yes | Q6: Yes | R6: Kenny | S6: =IFERROR(E6*L6,0) -> 13916167
A7: Calexico USD | B7: Calexico HS | C7: Sandra | D7: 11447 | E7: 13852000 | F7: Two Story | G7: 56 | H7: 45239 | I7: Approved | J7: Contract | K7: N/A | L7: 1 | M7: PB | N7: June, 2024 | P7: Yes | Q7: Yes | R7: Kenny | S7: =IFERROR(E7*L7,0) -> 13852000
A8: Lathrop Construction | B8: Santa Rosa Junior College - A1 RR | C8: Joe | D8: 11448 | E8: 129445 | F8: (1) 12x40 Restroom | G8: 1 | H8: 45243 | I8: Approved | J8: PO-1169-007 | K8: N/A | L8: 1 | M8: PB | N8: 45231 | O8: Yes | P8: Yes | Q8: Yes | R8: Moanes | S8: =IFERROR(E8*L8,0) -> 129445
A9: Corona-Norco | B9: Highland | C9: Sandra | D9: 11416 | E9: 3408324 | F9: (3) 72x40 & (1) 36x40 | G9: 21 | H9: 45299 | I9: Approved | J9: Contract | K9: N/A | L9: 1 | M9: PB | N9: 45505 | P9: Yes | Q9: Yes | R9: Mehdi | S9: =IFERROR(E9*L9,0) -> 3408324
A10: Corona-Norco | B10: Victress Bower | C10: Sandra | D10: 11417 | E10: 795151 | F10: 60x40 | G10: 5 | H10: 45302 | I10: Approved | J10: Contract | K10: N/A | L10: 1 | M10: PB | N10: 45505 | P10: Yes | Q10: Yes | R10: Mehdi | S10: =IFERROR(E10*L10,0) -> 795151
A11: Magnolia SD | B11: Dr. Albert Schweitzer | C11: Sandra | D11: 11443 | E11: 890992.27 | F11: 100x32 | G11: 10 | H11: 45308 | I11: Approved | J11: PO | K11: N/A | L11: 1 | M11: PB | N11: August, 2024 | P11: Yes | Q11: Yes | R11: Moanes | S11: =IFERROR(E11*L11,0) -> 890992.27
A12: Menifee USD | B12: Ridgemoor ES | C12: Sandra | D12: 11474 | E12: 2842622.5 | F12: (1) 144x40 & (1) 72x40 | G12: 18 | H12: 45309 | I12: Approved | J12: Contract | K12: N/A | L12: 1 | M12: PB | N12: Summer 2024 | P12: Yes | Q12: Yes | R12: Kenny | S12: =IFERROR(E12*L12,0) -> 2842622.5
A13: Magnolia SD | B13: Dr. Peter Marshall | C13: Sandra | D13: 11450 | E13: 1158613.1 | F13: 130x32 | G13: 13 | H13: 45317 | I13: Approved | J13: PO | K13: N/A | L13: 1 | M13: PB | N13: August, 2024 | P13: Yes | Q13: Yes | R13: Moanes | S13: =IFERROR(E13*L13,0) -> 1158613.1
A14: Hesperia Unified | B14: Mission Crest ES | C14: Sandra | D14: 11433 | E14: 863719 | F14: 72x40 TK | G14: 6 | H14: 45321 | I14: Approved | J14: Contract | K14: N/A | L14: 1 | M14: PB | N14: August, 2024 | P14: Yes | Q14: Yes | R14: Gino | S14: =IFERROR(E14*L14,0) -> 863719
A15: Hesperia Unified | B15: Maple School of Innovation | C15: Sandra | D15: 11436 | E15: 817329 | F15: 72x40 TK | G15: 6 | H15: 45322 | I15: Approved | J15: Contract | K15: N/A | L15: 1 | M15: PB | N15: August, 2024 | P15: Yes | Q15: Yes | R15: Gino | S15: =IFERROR(E15*L15,0) -> 817329
A16: Oro Grande SD | B16: Riverside Prep Weight Room | C16: Sandra | D16: 11444 | E16: 823142.22 | F16: 84X40 | G16: 7 | H16: 45330 | I16: Approved | J16: Contract | K16: N/A | L16: 1 | M16: PB | N16: Completed | P16: Yes | Q16: Yes | R16: Gino | S16: =IFERROR(E16*L16,0) -> 823142.22
A17: Chino Valley USD | B17: Cal Aero Preserve Acad | C17: Sandra | D17: 11453 | E17: 287193.06 | F17: 36x40 Fun Club | G17: 3 | H17: 45341 | I17: Approved | J17: PO 242047 | K17: N/A | L17: 1 | M17: PB | N17: 45505 | P17: Yes | Q17: Yes | R17: Mehdi | S17: =IFERROR(E17*L17,0) -> 287193.06
A18: Chino Valley USD | B18: E.J. Marshall ES | C18: Sandra | D18: 11454 | E18: 287193.06 | F18: 36X40 Fun Club | G18: 3 | H18: 45341 | I18: Approved | J18: PO 242044 | K18: N/A | L18: 1 | M18: PB | N18: 45505 | P18: Yes | Q18: Yes | R18: Mehdi | S18: =IFERROR(E18*L18,0) -> 287193.06
A19: Banning USD | B19: Florida Discovery PK | C19: Sandra | D19: 11475 | E19: 3242817 | F19: (2) 84x40 & (1) 72x40 | G19: 20 | H19: 45341 | I19: Approved | J19: Contract | K19: N/A | L19: 1 | M19: PB | N19: 45505 | P19: Yes | Q19: Yes | R19: Mehdi | S19: =IFERROR(E19*L19,0) -> 3242817
A20: Chino Valley USD | B20: Glenmeade ES | C20: Sandra | D20: 11452 | E20: 287193.06 | F20: 36X40 Fun Club | G20: 3 | H20: 45344 | I20: Approved | J20: PO 242038 | K20: N/A | L20: 1 | M20: PB | N20: 45505 | P20: Yes | Q20: Yes | R20: Mehdi | S20: =IFERROR(E20*L20,0) -> 287193.06
A21: Chino Valley USD | B21: Doris Dickson ES | C21: Sandra | D21: 11460 | E21: 287193.06 | F21: 36X40 Fun Club | G21: 3 | H21: 45349 | I21: Approved | J21: PO 242081 | K21: N/A | L21: 1 | M21: PB | N21: 45505 | P21: Yes | Q21: Yes | R21: Mehdi | S21: =IFERROR(E21*L21,0) -> 287193.06
A22: Hesperia Unified | B22: Lime Street ES TK | C22: Sandra | D22: 11437 | E22: 817329 | F22: 72X40 | G22: 6 | H22: 45349 | I22: Approved | J22: Contract | K22: N/A | L22: 1 | M22: PB | N22: August, 2024 | P22: Yes | Q22: Yes | R22: Gino | S22: =IFERROR(E22*L22,0) -> 817329
A23: Cajon Valley USD | B23: Anza ES | C23: Diana | D23: 11466 | E23: 335097.99 | F23: (3) 24x40 | G23: 6 | H23: 45351 | I23: Approved | J23: PO 12405687 | K23: N/A | L23: 1 | M23: PB | N23: 45505 | O23: 45239 | P23: Yes | Q23: Yes | R23: Gino | S23: =IFERROR(E23*L23,0) -> 335097.99
A24: Anaheim Union HSD | B24: Magnolia | C24: Sandra | D24: 11496 | E24: 126540.94 | F24: 8-6x16-7 Restroom | G24: 1 | H24: 45364 | I24: Approved | J24: Contract | K24: N/A | L24: 1 | M24: PB | N24: 45383 | P24: Yes | Q24: Yes | R24: Gino | S24: =IFERROR(E24*L24,0) -> 126540.94
A25: Cajon Valley USD | B25: Rancho San Diego ES | C25: Diana | D25: 11471 | E25: 251606.72 | F25: (2) 30x32 | G25: 6 | H25: 45352 | I25: Approved | J25: PO 12405692 | K25: N/A | L25: 1 | M25: PB | N25: 45505 | O25: 45239 | P25: Yes | Q25: Yes | R25: Gino | S25: =IFERROR(E25*L25,0) -> 251606.72
A26: Chino Valley USD | B26: Michael G. Wickman ES | C26: Sandra | D26: 11455 | E26: 287193.06 | F26: 36x40 Fun Club | G26: 3 | H26: 45355 | I26: Approved | J26: PO 242050 | K26: N/A | L26: 1 | M26: PB | N26: 45505 | P26: Yes | Q26: Yes | R26: Mehdi | S26: =IFERROR(E26*L26,0) -> 287193.06
A27: Cajon Valley USD | B27: Flying Hills ES | C27: Diana | D27: 11468 | E27: 251606.72 | F27: (2) 30x32 | G27: 6 | H27: 45359 | I27: Approved | J27: PO 12405689 | K27: N/A | L27: 1 | M27: PB | N27: 45505 | O27: 45239 | P27: Yes | Q27: Yes | R27: Gino | S27: =IFERROR(E27*L27,0) -> 251606.72
A28: Cajon Valley USD | B28: Naranca ES | C28: Diana | D28: 11470 | E28: 132697 | F28: (1) 24x40 w/RR | G28: 2 | H28: 45362 | I28: Approved | J28: PO 12450691 | K28: N/A | L28: 1 | M28: PB | N28: 45505 | O28: 45239 | P28: Yes | Q28: Yes | R28: Gino | S28: =IFERROR(E28*L28,0) -> 132697
A29: Hesperia Unified | B29: Cottonwood ES | C29: Sandra | D29: 11440 | E29: 817329 | F29: 72X40 TK | G29: 6 | H29: 45362 | I29: Approved | J29: Contract | K29: N/A | L29: 1 | M29: PB | N29: July, 2024 | P29: Yes | Q29: Yes | R29: Gino | S29: =IFERROR(E29*L29,0) -> 817329
A30: Hesperia Unified | B30: Kingston ES | C30: Sandra | D30: 11438 | E30: 817329 | F30: 72x40 TK | G30: 6 | H30: 45369 | I30: Approved | J30: Contract | K30: N/A | L30: 1 | M30: PB | N30: July, 2024 | P30: Yes | Q30: Yes | R30: Gino | S30: =IFERROR(E30*L30,0) -> 817329
A31: Cajon Valley USD | B31: Hillsdale MS | C31: Diana | D31: 11469 | E31: 194365.2 | F31: (1) 12x40 RR | G31: 1 | H31: 45371 | I31: Approved | J31: PO 12405690 | K31: N/A | L31: 1 | M31: PB | N31: 45505 | O31: 45239 | P31: Yes | Q31: Yes | R31: Gino | S31: =IFERROR(E31*L31,0) -> 194365.2
A32: Anaheim ESD | B32: Jefferson | C32: Sandra | D32: 11494 | E32: 637606.79 | F32: (1) 24x40 and (1) 12x40 Restroom | G32: 7 | H32: 45377 | I32: Approved | J32: LOI | K32: Shipped | L32: 1 | M32: PB | N32: Summer 2024 | P32: Yes | R32: Moanes | S32: =IFERROR(E32*L32,0) -> 637606.79
A33: Hesperia Unified | B33: Mesquite Trails ES 72X40 TK | C33: Sandra | D33: 11434 | E33: 817329 | F33: 72X40 TK | G33: 6 | H33: 45377 | I33: Approved | J33: Contract | K33: N/A | L33: 1 | M33: PB | N33: August, 2024 | P33: Yes | Q33: Yes | R33: Gino | S33: =IFERROR(E33*L33,0) -> 817329
A34: Hesperia Unified | B34: Eucalyptus | C34: Sandra | D34: 11439 | E34: 817329 | F34: 72X40 TK | G34: 6 | H34: 45383 | I34: Approved | J34: Contract | K34: N/A | L34: 1 | M34: PB | N34: July, 2024 | P34: Yes | Q34: Yes | R34: Gino | S34: =IFERROR(E34*L34,0) -> 817329
A35: Helendale SD | B35: Helendale | C35: Sandra | D35: 11504 | E35: 298215.84 | F35: (2) 24x40 | G35: 4 | H35: 45387 | I35: Approved | J35: PO 240296 | K35: N/A | L35: 1 | M35: PB | N35: 45474 | P35: Yes | Q35: Yes | R35: Moanes | S35: =IFERROR(E35*L35,0) -> 298215.84
A36: Walnut Valley USD | B36: Evergreen ES | C36: Sandra | D36: 11430 | E36: 326942.82 | F36: 36x40 Daycare | G36: 3 | H36: 45390 | I36: Approved | J36: P23-04716 | K36: Shipped | L36: 1 | M36: PB | P36: Yes | Q36: Yes | R36: Moanes | S36: =IFERROR(E36*L36,0) -> 326942.82
A37: Helendale SD | B37: Helendale | C37: Sandra | D37: 11427 | E37: 391547.55 | F37: (1) 36x40 | G37: 3 | H37: 45392 | I37: Approved | J37: PO | K37: N/A | L37: 1 | M37: PB | N37: 45474 | P37: Yes | Q37: Yes | R37: Moanes | S37: =IFERROR(E37*L37,0) -> 391547.55
A38: Cajon Valley USD | B38: Crest ES | C38: Diana | D38: 11467 | E38: 256043.7 | F38: (2) 30x32 | G38: 6 | H38: 45393 | I38: Approved | J38: PO 12405688 | K38: N/A | L38: 1 | M38: PB | N38: 45505 | O38: 45239 | P38: Yes | Q38: Yes | R38: Gino | S38: =IFERROR(E38*L38,0) -> 256043.7
A39: Sylvan USD | B39: Ustach MS | C39: Joe | D39: 11482 | E39: 325719.08 | F39: (2) 24x40 CR | G39: 4 | H39: 45393 | I39: Approved | J39: PO 242111 | K39: N/A | L39: 1 | M39: PB | N39: 45509 | O39: Yes | P39: Yes | Q39: Yes | R39: Kenny | S39: =IFERROR(E39*L39,0) -> 325719.08
A40: Sylvan USD | B40: Freedom ES | C40: Joe | D40: 11478 | E40: 325719.08 | F40: (2) 24x40 CR | G40: 4 | H40: 45394 | I40: Approved | J40: PO 242113 | K40: N/A | L40: 1 | M40: PB | N40: 45509 | O40: Yes | P40: Yes | Q40: Yes | R40: Kenny | S40: =IFERROR(E40*L40,0) -> 325719.08
...

Sheet Closed Deals 25
A1: SCM Sales Pipeline 2025
A2: Customer | B2: Project Name | C2: BDM | D2: Job Number | E2: Contract Value | F2: Building(s) | G2: Floor(s) | H2: Start Date for Production | I2: District Occupancy Date | J2: Confidence Level | K2: Current Status/Notes | L2: Contract Type | M2: Bid Piggyback | N2: Most Recent Proposal (Date) | O2: Job Release [BDM & DH] (Date) | P2: Engineering Release [BDM & Engineer] (Date) | Q2: Hand-off Meeting [BDM & PM] (Date) | R2: Kick-off Meeting [PM & ALL Depts] (Date) | S2: PM | T2: Estimated Value | U2: Estimated DSA Approval (per Engineering) | V2: Quarter | W2: Edited
A3: Apple Valley USD | B3: Sandia Academy | C3: Diana | D3: 11488 | E3: 1444491.4 | F3: (2) 72X40 | G3: 12 | H3: 45664 | I3: 45810 | J3: 1 | L3: Yes | M3: BID | R3: TBD | S3: Gino | T3: =IFERROR(E3*J3,0) -> 1444491.4 | U3: Approved | V3: =IFERROR(ROUNDUP(MONTH(IF(H3<>"",H3,""))/3, 0),"TBD") -> 1 | W3: =IF(I3<>"",IF(W3="",NOW(),W3),"") -> 45692.547
A4: Lancaster SD | B4: Lincoln Elementary | C4: Sandra | D4: 11520 | E4: 112000 | F4: 8'6" x 21'-6" RR | G4: 1 | H4: 45672 | I4: 45823 | J4: 1 | K4: Project Completed | L4: PO | M4: PB | N4: Yes | O4: No | P4: No | S4: Gino | T4: =IFERROR(E4*J4,0) -> 112000 | U4: Approved | V4: =IFERROR(ROUNDUP(MONTH(IF(H4<>"",H4,""))/3, 0),"TBD") -> 1 | W4: =IF(I4<>"",IF(W4="",NOW(),W4),"") -> 45813.652
A5: Fountain Valley SD | B5: Oka ES | C5: Sandra | D5: 11530 | E5: 262487.93 | F5: (1) 48'x40' | G5: 4 | H5: 45673 | I5: 45823 | J5: 1 | K5: Delivered and Completed | L5: Yes | M5: PB | O5: Yes | S5: Moanes | T5: =IFERROR(E5*J5,0) -> 262487.93 | U5: Approved | V5: =IFERROR(ROUNDUP(MONTH(IF(H5<>"",H5,""))/3, 0),"TBD") -> 1 | W5: =IF(I5<>"",IF(W5="",NOW(),W5),"") -> 45692.547
A6: Fountain Valley SD | B6: Newland ES | C6: Sandra | D6: 11529 | E6: 138298.63 | F6: (1) 24'X40' | G6: 2 | H6: 45678 | I6: 45823 | J6: 1 | K6: Delivered and Completed | L6: Yes | M6: PB | O6: Yes | S6: Moanes | T6: =IFERROR(E6*J6,0) -> 138298.63 | U6: Approved | V6: =IFERROR(ROUNDUP(MONTH(IF(H6<>"",H6,""))/3, 0),"TBD") -> 1 | W6: =IF(I6<>"",IF(W6="",NOW(),W6),"") -> 45692.547
A7: Apple Valley USD | B7: Yucca Loma ES | C7: Sandra | D7: 11489 | E7: 1444491.4 | F7: (2) 72X40 | G7: 12 | H7: 45679 | I7: 45811 | J7: 1 | K7: Delivery March 3/4/25 | L7: Yes | M7: Bid | R7: TBD | S7: Gino | T7: =IFERROR(E7*J7,0) -> 1444491.4 | U7: Approved | V7: =IFERROR(ROUNDUP(MONTH(IF(H7<>"",H7,""))/3, 0),"TBD") -> 1 | W7: =IF(I7<>"",IF(W7="",NOW(),W7),"") -> 45692.547
A8: Fountain Valley SD | B8: Plavan ES | C8: Sandra | D8: 11528 | E8: 260370.01 | F8: (1) 48'x40' | G8: 4 | H8: 45680 | I8: 45823 | J8: 1 | L8: Yes | M8: PB | O8: Yes | S8: Moanes | T8: =IFERROR(E8*J8,0) -> 260370.01 | U8: Approved | V8: =IFERROR(ROUNDUP(MONTH(IF(H8<>"",H8,""))/3, 0),"TBD") -> 1 | W8: =IF(I8<>"",IF(W8="",NOW(),W8),"") -> 45692.547
A9: Torrance USD | B9: Torrance ES | C9: Sandra | D9: 11501 | E9: 2448024.2 | F9: (1) 168'x40' | G9: 14 | H9: 45685 | I9: 45901 | J9: 1 | K9: Bldg Onsite | L9: PO | M9: PB | O9: Yes | P9: Yes | S9: Moanes | T9: =IFERROR(E9*J9,0) -> 2448024.2 | U9: Approved | V9: =IFERROR(ROUNDUP(MONTH(IF(H9<>"",H9,""))/3, 0),"TBD") -> 1 | W9: =IF(I9<>"",IF(W9="",NOW(),W9),"") -> 45692.547
A10: Modesto CS | B10: Beyer HS | C10: Joe | D10: 11574 | E10: 246171.81 | F10: (1) 12x40 RR Model C-2 | G10: 1 | H10: 45694 | I10: 45778 | J10: 1 | K10: DSA approved on 11/8/2024 Boyer has been hired by District as GC | L10: PO 251803 | M10: PB | N10: 45551 | O10: 45553 | P10: Yes | S10: Joe | T10: =IFERROR(E10*J10,0) -> 246171.81 | U10: Approved | V10: =IFERROR(ROUNDUP(MONTH(IF(H10<>"",H10,""))/3, 0),"TBD") -> 1 | W10: =IF(I10<>"",IF(W10="",NOW(),W10),"") -> 45692.547
A11: Rio Hondo College | B11: Fire Academy | C11: Sandra | D11: 11442 | E11: 227900.33 | F11: 24x60 Classroom & Office | G11: 2 | H11: 45694 | I11: 45777 | J11: 1 | K11: Bldg Onsite | L11: PO1-230000002430 | O11: Yes | P11: Yes | S11: Moanes | T11: =IFERROR(E11*J11,0) -> 227900.33 | U11: Approved | V11: =IFERROR(ROUNDUP(MONTH(IF(H11<>"",H11,""))/3, 0),"TBD") -> 1 | W11: =IF(I11<>"",IF(W11="",NOW(),W11),"") -> 45692.547
A12: Corona Norco USD | B12: Harada ES | C12: Sandra | D12: 11558 | E12: 998332 | F12: (3) 36x40 | G12: 9 | H12: 45695 | I12: 45768 | J12: 1 | K12: Bldg Onsite | L12: Yes | M12: Bid | R12: TBD | S12: Gino | T12: =IFERROR(E12*J12,0) -> 998332 | U12: Approved | V12: =IFERROR(ROUNDUP(MONTH(IF(H12<>"",H12,""))/3, 0),"TBD") -> 1 | W12: =IF(I12<>"",IF(W12="",NOW(),W12),"") -> 45692.547
A13: Vineland SD | B13: Vineland ES | C13: Joe | D13: 11502 | E13: 3006336.8 | F13: (7) 36X40 Pre-K, TK, Kinder CR | G13: 21 | H13: 45702 | I13: 45812 | J13: 1 | K13: DSA approved 12/4/2024 6 calendar months for delivery after DSA approval | L13: PO 240532 | M13: Bid | N13: Bid | O13: 45383 | P13: Yes | S13: Kenny | T13: =IFERROR(E13*J13,0) -> 3006336.8 | U13: Approved | V13: =IFERROR(ROUNDUP(MONTH(IF(H13<>"",H13,""))/3, 0),"TBD") -> 1 | W13: =IF(I13<>"",IF(W13="",NOW(),W13),"") -> 45692.547
A14: Corona Norco USD | B14: Temescal ES | C14: Sandra | D14: 11559 | E14: 332944 | F14: (1) 36x40 | G14: 3 | H14: 45706 | I14: 45778 | J14: 1 | K14: Bldg Onsite | L14: Yes | M14: Bid | R14: TBD | S14: Gino | T14: =IFERROR(E14*J14,0) -> 332944 | U14: Approved | V14: =IFERROR(ROUNDUP(MONTH(IF(H14<>"",H14,""))/3, 0),"TBD") -> 1 | W14: =IF(I14<>"",IF(W14="",NOW(),W14),"") -> 45692.547
A15: Corona Norco USD | B15: Jefferson ES | C15: Sandra | D15: 11560 | E15: 792600 | F15: (4) 30x32 | G15: 12 | H15: 45709 | I15: 45743 | J15: 1 | K15: Bldg Onsite | L15: Yes | M15: Bid | S15: Gino | T15: =IFERROR(E15*J15,0) -> 792600 | U15: Approved | V15: =IFERROR(ROUNDUP(MONTH(IF(H15<>"",H15,""))/3, 0),"TBD") -> 1 | W15: =IF(I15<>"",IF(W15="",NOW(),W15),"") -> 45692.547
A16: Cajon Valley USD | B16: Meridian ES | C16: Diana | D16: 11519 | E16: 199336 | F16: (1) 12'x40' Restroom Bldg. Model C-2 | G16: 1 | H16: 45723 | I16: 45839 | J16: 1 | K16: No site dates available | L16: PO 12500433 | M16: PB | S16: Gino | T16: =IFERROR(E16*J16,0) -> 199336 | U16: Approved | V16: =IFERROR(ROUNDUP(MONTH(IF(H16<>"",H16,""))/3, 0),"TBD") -> 1 | W16: =IF(I16<>"",IF(W16="",NOW(),W16),"") -> 45692.547
A17: Menifee USD | B17: Hans Christensen ES | C17: Diana | D17: 11588 | E17: 3084567.3 | F17: 180’x40’ TK | G17: 15 | H17: 45726 | I17: 45838 | J17: 1 | L17: Agreement received 12/24 | M17: Bid | R17: TBD | S17: Kenny | T17: =IFERROR(E17*J17,0) -> 3084567.3 | U17: Approved | V17: =IFERROR(ROUNDUP(MONTH(IF(H17<>"",H17,""))/3, 0),"TBD") -> 1 | W17: =IF(I17<>"",IF(W17="",NOW(),W17),"") -> 45692.547
